Workbook

Sheet Cómo usar
A1: Archivo maestro — solo para el coordinador (Gabriel). NO enviarlo a los revisores.
A3: 1. Cuando ambos revisores entreguen, copia «Causa (A–G)» (E2:E29) de cada uno y pégala como VALORES en la columna amarilla
A4: de «R1 respuestas» y «R2 respuestas» (Confianza y Notas son opcionales).
A5: 2. Revisa «Análisis». Si aparece «INVÁLIDO», corrige ese código: solo se aceptan A, B, C, D, E, F o G.
A6: 3. Registra el kappa y su IC 95 % ANTES del consenso: es la medida de confiabilidad.
A7: 4. Discutan los eventos marcados «no» y escriban la causa final en «Consenso».
A8: 5. El estudio está cerrado cuando «Estado» dice CERRADO: 28 respuestas válidas por revisor y 0 desacuerdos sin consenso.
A10: Intervalo de confianza (resultado principal = bootstrap):
A11: • Ejecuta: python kappa_bootstrap.py maestro_analisis_kappa.xlsx → escribe kappa e IC 95 % en la hoja «IC bootstrap». Ese es el que va al paper.
A12: • La sección «Comprobación opcional» de «Análisis» (Fleiss, Cohen y Everitt 1969; verificada contra statsmodels) es solo un control.
A13: • Si todos los eventos caen en una sola causa y ambos coinciden, el kappa es indefinido (pe = 1): se reporta solo el acuerdo observado.
A14: • Los rangos de interpretación del kappa (p. ej., 0,61–0,80 «sustancial», Landis y Koch 1977) son orientativos.

Sheet R1 respuestas
A1: Evento | B1: Causa (pegar) | C1: Confianza (pegar) | D1: Notas (pegar)
A2: 1
A3: 2
A4: 3
A5: 4
A6: 5
A7: 6
A8: 7
A9: 8
A10: 9
A11: 10
A12: 11
A13: 12
... A29: 28

Sheet R2 respuestas
A1: Evento | B1: Causa (pegar) | C1: Confianza (pegar) | D1: Notas (pegar)
A2: 1
A3: 2
A4: 3
A5: 4
A6: 5
A7: 6
A8: 7
A9: 8
A10: 9
A11: 10
A12: 11
A13: 12
... A29: 28

Sheet Análisis
A1: Evento | B1: Revisor 1 | C1: Revisor 2 | D1: ¿Coinciden? | E1: Consenso (escribir) | F1: Pendiente | G1: Causa final | H1: Estado del estudio
A2: ='R1 respuestas'!A2 -> 1 | B2: =IF(TRIM('R1 respuestas'!B2)="","",IF(ISNUMBER(SEARCH("|"&UPPER(TRIM('R1 respuestas'!B2))&"|","|A|B|C|D|E|F|G|")),UPPER(TRIM('R1 respuestas'!B2)),"INVÁLIDO")) | C2: =IF(TRIM('R2 respuestas'!B2)="","",IF(ISNUMBER(SEARCH("|"&UPPER(TRIM('R2 respuestas'!B2))&"|","|A|B|C|D|E|F|G|")),UPPER(TRIM('R2 respuestas'!B2)),"INVÁLIDO")) | D2: =IF(OR(B2="",C2="",B2="INVÁLIDO",C2="INVÁLIDO"),"",IF(B2=C2,"sí","no")) | F2: =IF(OR(B2="",C2=""),"FALTA RESPUESTA",IF(OR(B2="INVÁLIDO",C2="INVÁLIDO"),"CÓDIGO INVÁLIDO",IF(IF(TRIM(E2)="","",IF(ISNUMBER(SEARCH("|"&UPPER(TRIM(E2))&"|","|A|B|C|D|E|F|G|")),UPPER(TRIM(E2)),"INVÁLIDO"))="INVÁLIDO","CONSENSO INVÁLIDO",IF(AND(D2="no",IF(TRIM(E2)="","",IF(ISNUMBER(SEARCH("|"&UPPER(TRIM(E2))&"|","|A|B|C|D|E|F|G|")),UPPER(TRIM(E2)),"INVÁLIDO"))=""),"FALTA CONSENSO","")))) -> FALTA RESPUESTA | G2: =IF(F2<>"","",IF(IF(TRIM(E2)="","",IF(ISNUMBER(SEARCH("|"&UPPER(TRIM(E2))&"|","|A|B|C|D|E|F|G|")),UPPER(TRIM(E2)),"INVÁLIDO"))<>"",IF(TRIM(E2)="","",IF(ISNUMBER(SEARCH("|"&UPPER(TRIM(E2))&"|","|A|B|C|D|E|F|G|")),UPPER(TRIM(E2)),"INVÁLIDO")),B2)) | H2: Respuestas válidas Revisor 1 | I2: =SUMPRODUCT(--ISNUMBER(MATCH(B2:B29,{"A","B","C","D","E","F","G"},0))) -> 0
A3: ='R1 respuestas'!A3 -> 2 | B3: =IF(TRIM('R1 respuestas'!B3)="","",IF(ISNUMBER(SEARCH("|"&UPPER(TRIM('R1 respuestas'!B3))&"|","|A|B|C|D|E|F|G|")),UPPER(TRIM('R1 respuestas'!B3)),"INVÁLIDO")) | C3: =IF(TRIM('R2 respuestas'!B3)="","",IF(ISNUMBER(SEARCH("|"&UPPER(TRIM('R2 respuestas'!B3))&"|","|A|B|C|D|E|F|G|")),UPPER(TRIM('R2 respuestas'!B3)),"INVÁLIDO")) | D3: =IF(OR(B3="",C3="",B3="INVÁLIDO",C3="INVÁLIDO"),"",IF(B3=C3,"sí","no")) | F3: =IF(OR(B3="",C3=""),"FALTA RESPUESTA",IF(OR(B3="INVÁLIDO",C3="INVÁLIDO"),"CÓDIGO INVÁLIDO",IF(IF(TRIM(E3)="","",IF(ISNUMBER(SEARCH("|"&UPPER(TRIM(E3))&"|","|A|B|C|D|E|F|G|")),UPPER(TRIM(E3)),"INVÁLIDO"))="INVÁLIDO","CONSENSO INVÁLIDO",IF(AND(D3="no",IF(TRIM(E3)="","",IF(ISNUMBER(SEARCH("|"&UPPER(TRIM(E3))&"|","|A|B|C|D|E|F|G|")),UPPER(TRIM(E3)),"INVÁLIDO"))=""),"FALTA CONSENSO","")))) -> FALTA RESPUESTA | G3: =IF(F3<>"","",IF(IF(TRIM(E3)="","",IF(ISNUMBER(SEARCH("|"&UPPER(TRIM(E3))&"|","|A|B|C|D|E|F|G|")),UPPER(TRIM(E3)),"INVÁLIDO"))<>"",IF(TRIM(E3)="","",IF(ISNUMBER(SEARCH("|"&UPPER(TRIM(E3))&"|","|A|B|C|D|E|F|G|")),UPPER(TRIM(E3)),"INVÁLIDO")),B3)) | H3: Respuestas válidas Revisor 2 | I3: =SUMPRODUCT(--ISNUMBER(MATCH(C2:C29,{"A","B","C","D","E","F","G"},0))) -> 0
A4: ='R1 respuestas'!A4 -> 3 | B4: =IF(TRIM('R1 respuestas'!B4)="","",IF(ISNUMBER(SEARCH("|"&UPPER(TRIM('R1 respuestas'!B4))&"|","|A|B|C|D|E|F|G|")),UPPER(TRIM('R1 respuestas'!B4)),"INVÁLIDO")) | C4: =IF(TRIM('R2 respuestas'!B4)="","",IF(ISNUMBER(SEARCH("|"&UPPER(TRIM('R2 respuestas'!B4))&"|","|A|B|C|D|E|F|G|")),UPPER(TRIM('R2 respuestas'!B4)),"INVÁLIDO")) | D4: =IF(OR(B4="",C4="",B4="INVÁLIDO",C4="INVÁLIDO"),"",IF(B4=C4,"sí","no")) | F4: =IF(OR(B4="",C4=""),"FALTA RESPUESTA",IF(OR(B4="INVÁLIDO",C4="INVÁLIDO"),"CÓDIGO INVÁLIDO",IF(IF(TRIM(E4)="","",IF(ISNUMBER(SEARCH("|"&UPPER(TRIM(E4))&"|","|A|B|C|D|E|F|G|")),UPPER(TRIM(E4)),"INVÁLIDO"))="INVÁLIDO","CONSENSO INVÁLIDO",IF(AND(D4="no",IF(TRIM(E4)="","",IF(ISNUMBER(SEARCH("|"&UPPER(TRIM(E4))&"|","|A|B|C|D|E|F|G|")),UPPER(TRIM(E4)),"INVÁLIDO"))=""),"FALTA CONSENSO","")))) -> FALTA RESPUESTA | G4: =IF(F4<>"","",IF(IF(TRIM(E4)="","",IF(ISNUMBER(SEARCH("|"&UPPER(TRIM(E4))&"|","|A|B|C|D|E|F|G|")),UPPER(TRIM(E4)),"INVÁLIDO"))<>"",IF(TRIM(E4)="","",IF(ISNUMBER(SEARCH("|"&UPPER(TRIM(E4))&"|","|A|B|C|D|E|F|G|")),UPPER(TRIM(E4)),"INVÁLIDO")),B4)) | H4: Códigos inválidos | I4: =COUNTIF(B2:B29,"INVÁLIDO")+COUNTIF(C2:C29,"INVÁLIDO") -> 0
A5: ='R1 respuestas'!A5 -> 4 | B5: =IF(TRIM('R1 respuestas'!B5)="","",IF(ISNUMBER(SEARCH("|"&UPPER(TRIM('R1 respuestas'!B5))&"|","|A|B|C|D|E|F|G|")),UPPER(TRIM('R1 respuestas'!B5)),"INVÁLIDO")) | C5: =IF(TRIM('R2 respuestas'!B5)="","",IF(ISNUMBER(SEARCH("|"&UPPER(TRIM('R2 respuestas'!B5))&"|","|A|B|C|D|E|F|G|")),UPPER(TRIM('R2 respuestas'!B5)),"INVÁLIDO")) | D5: =IF(OR(B5="",C5="",B5="INVÁLIDO",C5="INVÁLIDO"),"",IF(B5=C5,"sí","no")) | F5: =IF(OR(B5="",C5=""),"FALTA RESPUESTA",IF(OR(B5="INVÁLIDO",C5="INVÁLIDO"),"CÓDIGO INVÁLIDO",IF(IF(TRIM(E5)="","",IF(ISNUMBER(SEARCH("|"&UPPER(TRIM(E5))&"|","|A|B|C|D|E|F|G|")),UPPER(TRIM(E5)),"INVÁLIDO"))="INVÁLIDO","CONSENSO INVÁLIDO",IF(AND(D5="no",IF(TRIM(E5)="","",IF(ISNUMBER(SEARCH("|"&UPPER(TRIM(E5))&"|","|A|B|C|D|E|F|G|")),UPPER(TRIM(E5)),"INVÁLIDO"))=""),"FALTA CONSENSO","")))) -> FALTA RESPUESTA | G5: =IF(F5<>"","",IF(IF(TRIM(E5)="","",IF(ISNUMBER(SEARCH("|"&UPPER(TRIM(E5))&"|","|A|B|C|D|E|F|G|")),UPPER(TRIM(E5)),"INVÁLIDO"))<>"",IF(TRIM(E5)="","",IF(ISNUMBER(SEARCH("|"&UPPER(TRIM(E5))&"|","|A|B|C|D|E|F|G|")),UPPER(TRIM(E5)),"INVÁLIDO")),B5)) | H5: Desacuerdos sin consenso | I5: =COUNTIF(F2:F29,"FALTA CONSENSO") -> 0
A6: ='R1 respuestas'!A6 -> 5 | B6: =IF(TRIM('R1 respuestas'!B6)="","",IF(ISNUMBER(SEARCH("|"&UPPER(TRIM('R1 respuestas'!B6))&"|","|A|B|C|D|E|F|G|")),UPPER(TRIM('R1 respuestas'!B6)),"INVÁLIDO")) | C6: =IF(TRIM('R2 respuestas'!B6)="","",IF(ISNUMBER(SEARCH("|"&UPPER(TRIM('R2 respuestas'!B6))&"|","|A|B|C|D|E|F|G|")),UPPER(TRIM('R2 respuestas'!B6)),"INVÁLIDO")) | D6: =IF(OR(B6="",C6="",B6="INVÁLIDO",C6="INVÁLIDO"),"",IF(B6=C6,"sí","no")) | F6: =IF(OR(B6="",C6=""),"FALTA RESPUESTA",IF(OR(B6="INVÁLIDO",C6="INVÁLIDO"),"CÓDIGO INVÁLIDO",IF(IF(TRIM(E6)="","",IF(ISNUMBER(SEARCH("|"&UPPER(TRIM(E6))&"|","|A|B|C|D|E|F|G|")),UPPER(TRIM(E6)),"INVÁLIDO"))="INVÁLIDO","CONSENSO INVÁLIDO",IF(AND(D6="no",IF(TRIM(E6)="","",IF(ISNUMBER(SEARCH("|"&UPPER(TRIM(E6))&"|","|A|B|C|D|E|F|G|")),UPPER(TRIM(E6)),"INVÁLIDO"))=""),"FALTA CONSENSO","")))) -> FALTA RESPUESTA | G6: =IF(F6<>"","",IF(IF(TRIM(E6)="","",IF(ISNUMBER(SEARCH("|"&UPPER(TRIM(E6))&"|","|A|B|C|D|E|F|G|")),UPPER(TRIM(E6)),"INVÁLIDO"))<>"",IF(TRIM(E6)="","",IF(ISNUMBER(SEARCH("|"&UPPER(TRIM(E6))&"|","|A|B|C|D|E|F|G|")),UPPER(TRIM(E6)),"INVÁLIDO")),B6)) | H6: Consensos con código inválido | I6: =COUNTIF(F2:F29,"CONSENSO INVÁLIDO") -> 0
A7: ='R1 respuestas'!A7 -> 6 | B7: =IF(TRIM('R1 respuestas'!B7)="","",IF(ISNUMBER(SEARCH("|"&UPPER(TRIM('R1 respuestas'!B7))&"|","|A|B|C|D|E|F|G|")),UPPER(TRIM('R1 respuestas'!B7)),"INVÁLIDO")) | C7: =IF(TRIM('R2 respuestas'!B7)="","",IF(ISNUMBER(SEARCH("|"&UPPER(TRIM('R2 respuestas'!B7))&"|","|A|B|C|D|E|F|G|")),UPPER(TRIM('R2 respuestas'!B7)),"INVÁLIDO")) | D7: =IF(OR(B7="",C7="",B7="INVÁLIDO",C7="INVÁLIDO"),"",IF(B7=C7,"sí","no")) | F7: =IF(OR(B7="",C7=""),"FALTA RESPUESTA",IF(OR(B7="INVÁLIDO",C7="INVÁLIDO"),"CÓDIGO INVÁLIDO",IF(IF(TRIM(E7)="","",IF(ISNUMBER(SEARCH("|"&UPPER(TRIM(E7))&"|","|A|B|C|D|E|F|G|")),UPPER(TRIM(E7)),"INVÁLIDO"))="INVÁLIDO","CONSENSO INVÁLIDO",IF(AND(D7="no",IF(TRIM(E7)="","",IF(ISNUMBER(SEARCH("|"&UPPER(TRIM(E7))&"|","|A|B|C|D|E|F|G|")),UPPER(TRIM(E7)),"INVÁLIDO"))=""),"FALTA CONSENSO","")))) -> FALTA RESPUESTA | G7: =IF(F7<>"","",IF(IF(TRIM(E7)="","",IF(ISNUMBER(SEARCH("|"&UPPER(TRIM(E7))&"|","|A|B|C|D|E|F|G|")),UPPER(TRIM(E7)),"INVÁLIDO"))<>"",IF(TRIM(E7)="","",IF(ISNUMBER(SEARCH("|"&UPPER(TRIM(E7))&"|","|A|B|C|D|E|F|G|")),UPPER(TRIM(E7)),"INVÁLIDO")),B7)) | H7: Eventos con causa final válida | I7: =COUNTIF(G2:G29,"?*") -> 0
A8: ='R1 respuestas'!A8 -> 7 | B8: =IF(TRIM('R1 respuestas'!B8)="","",IF(ISNUMBER(SEARCH("|"&UPPER(TRIM('R1 respuestas'!B8))&"|","|A|B|C|D|E|F|G|")),UPPER(TRIM('R1 respuestas'!B8)),"INVÁLIDO")) | C8: =IF(TRIM('R2 respuestas'!B8)="","",IF(ISNUMBER(SEARCH("|"&UPPER(TRIM('R2 respuestas'!B8))&"|","|A|B|C|D|E|F|G|")),UPPER(TRIM('R2 respuestas'!B8)),"INVÁLIDO")) | D8: =IF(OR(B8="",C8="",B8="INVÁLIDO",C8="INVÁLIDO"),"",IF(B8=C8,"sí","no")) | F8: =IF(OR(B8="",C8=""),"FALTA RESPUESTA",IF(OR(B8="INVÁLIDO",C8="INVÁLIDO"),"CÓDIGO INVÁLIDO",IF(IF(TRIM(E8)="","",IF(ISNUMBER(SEARCH("|"&UPPER(TRIM(E8))&"|","|A|B|C|D|E|F|G|")),UPPER(TRIM(E8)),"INVÁLIDO"))="INVÁLIDO","CONSENSO INVÁLIDO",IF(AND(D8="no",IF(TRIM(E8)="","",IF(ISNUMBER(SEARCH("|"&UPPER(TRIM(E8))&"|","|A|B|C|D|E|F|G|")),UPPER(TRIM(E8)),"INVÁLIDO"))=""),"FALTA CONSENSO","")))) -> FALTA RESPUESTA | G8: =IF(F8<>"","",IF(IF(TRIM(E8)="","",IF(ISNUMBER(SEARCH("|"&UPPER(TRIM(E8))&"|","|A|B|C|D|E|F|G|")),UPPER(TRIM(E8)),"INVÁLIDO"))<>"",IF(TRIM(E8)="","",IF(ISNUMBER(SEARCH("|"&UPPER(TRIM(E8))&"|","|A|B|C|D|E|F|G|")),UPPER(TRIM(E8)),"INVÁLIDO")),B8)) | H8: Estado | I8: =IF(AND(I7=28,COUNTIF(F2:F29,"?*")=0),"CERRADO","incompleto") -> incompleto
A9: ='R1 respuestas'!A9 -> 8 | B9: =IF(TRIM('R1 respuestas'!B9)="","",IF(ISNUMBER(SEARCH("|"&UPPER(TRIM('R1 respuestas'!B9))&"|","|A|B|C|D|E|F|G|")),UPPER(TRIM('R1 respuestas'!B9)),"INVÁLIDO")) | C9: =IF(TRIM('R2 respuestas'!B9)="","",IF(ISNUMBER(SEARCH("|"&UPPER(TRIM('R2 respuestas'!B9))&"|","|A|B|C|D|E|F|G|")),UPPER(TRIM('R2 respuestas'!B9)),"INVÁLIDO")) | D9: =IF(OR(B9="",C9="",B9="INVÁLIDO",C9="INVÁLIDO"),"",IF(B9=C9,"sí","no")) | F9: =IF(OR(B9="",C9=""),"FALTA RESPUESTA",IF(OR(B9="INVÁLIDO",C9="INVÁLIDO"),"CÓDIGO INVÁLIDO",IF(IF(TRIM(E9)="","",IF(ISNUMBER(SEARCH("|"&UPPER(TRIM(E9))&"|","|A|B|C|D|E|F|G|")),UPPER(TRIM(E9)),"INVÁLIDO"))="INVÁLIDO","CONSENSO INVÁLIDO",IF(AND(D9="no",IF(TRIM(E9)="","",IF(ISNUMBER(SEARCH("|"&UPPER(TRIM(E9))&"|","|A|B|C|D|E|F|G|")),UPPER(TRIM(E9)),"INVÁLIDO"))=""),"FALTA CONSENSO","")))) -> FALTA RESPUESTA | G9: =IF(F9<>"","",IF(IF(TRIM(E9)="","",IF(ISNUMBER(SEARCH("|"&UPPER(TRIM(E9))&"|","|A|B|C|D|E|F|G|")),UPPER(TRIM(E9)),"INVÁLIDO"))<>"",IF(TRIM(E9)="","",IF(ISNUMBER(SEARCH("|"&UPPER(TRIM(E9))&"|","|A|B|C|D|E|F|G|")),UPPER(TRIM(E9)),"INVÁLIDO")),B9))
A10: ='R1 respuestas'!A10 -> 9 | B10: =IF(TRIM('R1 respuestas'!B10)="","",IF(ISNUMBER(SEARCH("|"&UPPER(TRIM('R1 respuestas'!B10))&"|","|A|B|C|D|E|F|G|")),UPPER(TRIM('R1 respuestas'!B10)),"INVÁLIDO")) | C10: =IF(TRIM('R2 respuestas'!B10)="","",IF(ISNUMBER(SEARCH("|"&UPPER(TRIM('R2 respuestas'!B10))&"|","|A|B|C|D|E|F|G|")),UPPER(TRIM('R2 respuestas'!B10)),"INVÁLIDO")) | D10: =IF(OR(B10="",C10="",B10="INVÁLIDO",C10="INVÁLIDO"),"",IF(B10=C10,"sí","no")) | F10: =IF(OR(B10="",C10=""),"FALTA RESPUESTA",IF(OR(B10="INVÁLIDO",C10="INVÁLIDO"),"CÓDIGO INVÁLIDO",IF(IF(TRIM(E10)="","",IF(ISNUMBER(SEARCH("|"&UPPER(TRIM(E10))&"|","|A|B|C|D|E|F|G|")),UPPER(TRIM(E10)),"INVÁLIDO"))="INVÁLIDO","CONSENSO INVÁLIDO",IF(AND(D10="no",IF(TRIM(E10)="","",IF(ISNUMBER(SEARCH("|"&UPPER(TRIM(E10))&"|","|A|B|C|D|E|F|G|")),UPPER(TRIM(E10)),"INVÁLIDO"))=""),"FALTA CONSENSO","")))) -> FALTA RESPUESTA | G10: =IF(F10<>"","",IF(IF(TRIM(E10)="","",IF(ISNUMBER(SEARCH("|"&UPPER(TRIM(E10))&"|","|A|B|C|D|E|F|G|")),UPPER(TRIM(E10)),"INVÁLIDO"))<>"",IF(TRIM(E10)="","",IF(ISNUMBER(SEARCH("|"&UPPER(TRIM(E10))&"|","|A|B|C|D|E|F|G|")),UPPER(TRIM(E10)),"INVÁLIDO")),B10)) | H10: Confiabilidad (respuestas originales, antes del consenso)
A11: ='R1 respuestas'!A11 -> 10 | B11: =IF(TRIM('R1 respuestas'!B11)="","",IF(ISNUMBER(SEARCH("|"&UPPER(TRIM('R1 respuestas'!B11))&"|","|A|B|C|D|E|F|G|")),UPPER(TRIM('R1 respuestas'!B11)),"INVÁLIDO")) | C11: =IF(TRIM('R2 respuestas'!B11)="","",IF(ISNUMBER(SEARCH("|"&UPPER(TRIM('R2 respuestas'!B11))&"|","|A|B|C|D|E|F|G|")),UPPER(TRIM('R2 respuestas'!B11)),"INVÁLIDO")) | D11: =IF(OR(B11="",C11="",B11="INVÁLIDO",C11="INVÁLIDO"),"",IF(B11=C11,"sí","no")) | F11: =IF(OR(B11="",C11=""),"FALTA RESPUESTA",IF(OR(B11="INVÁLIDO",C11="INVÁLIDO"),"CÓDIGO INVÁLIDO",IF(IF(TRIM(E11)="","",IF(ISNUMBER(SEARCH("|"&UPPER(TRIM(E11))&"|","|A|B|C|D|E|F|G|")),UPPER(TRIM(E11)),"INVÁLIDO"))="INVÁLIDO","CONSENSO INVÁLIDO",IF(AND(D11="no",IF(TRIM(E11)="","",IF(ISNUMBER(SEARCH("|"&UPPER(TRIM(E11))&"|","|A|B|C|D|E|F|G|")),UPPER(TRIM(E11)),"INVÁLIDO"))=""),"FALTA CONSENSO","")))) -> FALTA RESPUESTA | G11: =IF(F11<>"","",IF(IF(TRIM(E11)="","",IF(ISNUMBER(SEARCH("|"&UPPER(TRIM(E11))&"|","|A|B|C|D|E|F|G|")),UPPER(TRIM(E11)),"INVÁLIDO"))<>"",IF(TRIM(E11)="","",IF(ISNUMBER(SEARCH("|"&UPPER(TRIM(E11))&"|","|A|B|C|D|E|F|G|")),UPPER(TRIM(E11)),"INVÁLIDO")),B11)) | H11: Eventos con ambas respuestas válidas (n) | I11: =COUNTIF(D2:D29,"sí")+COUNTIF(D2:D29,"no") -> 0
A12: ='R1 respuestas'!A12 -> 11 | B12: =IF(TRIM('R1 respuestas'!B12)="","",IF(ISNUMBER(SEARCH("|"&UPPER(TRIM('R1 respuestas'!B12))&"|","|A|B|C|D|E|F|G|")),UPPER(TRIM('R1 respuestas'!B12)),"INVÁLIDO")) | C12: =IF(TRIM('R2 respuestas'!B12)="","",IF(ISNUMBER(SEARCH("|"&UPPER(TRIM('R2 respuestas'!B12))&"|","|A|B|C|D|E|F|G|")),UPPER(TRIM('R2 respuestas'!B12)),"INVÁLIDO")) | D12: =IF(OR(B12="",C12="",B12="INVÁLIDO",C12="INVÁLIDO"),"",IF(B12=C12,"sí","no")) | F12: =IF(OR(B12="",C12=""),"FALTA RESPUESTA",IF(OR(B12="INVÁLIDO",C12="INVÁLIDO"),"CÓDIGO INVÁLIDO",IF(IF(TRIM(E12)="","",IF(ISNUMBER(SEARCH("|"&UPPER(TRIM(E12))&"|","|A|B|C|D|E|F|G|")),UPPER(TRIM(E12)),"INVÁLIDO"))="INVÁLIDO","CONSENSO INVÁLIDO",IF(AND(D12="no",IF(TRIM(E12)="","",IF(ISNUMBER(SEARCH("|"&UPPER(TRIM(E12))&"|","|A|B|C|D|E|F|G|")),UPPER(TRIM(E12)),"INVÁLIDO"))=""),"FALTA CONSENSO","")))) -> FALTA RESPUESTA | G12: =IF(F12<>"","",IF(IF(TRIM(E12)="","",IF(ISNUMBER(SEARCH("|"&UPPER(TRIM(E12))&"|","|A|B|C|D|E|F|G|")),UPPER(TRIM(E12)),"INVÁLIDO"))<>"",IF(TRIM(E12)="","",IF(ISNUMBER(SEARCH("|"&UPPER(TRIM(E12))&"|","|A|B|C|D|E|F|G|")),UPPER(TRIM(E12)),"INVÁLIDO")),B12)) | H12: Coincidencias | I12: =COUNTIF(D2:D29,"sí") -> 0
A13: ='R1 respuestas'!A13 -> 12 | B13: =IF(TRIM('R1 respuestas'!B13)="","",IF(ISNUMBER(SEARCH("|"&UPPER(TRIM('R1 respuestas'!B13))&"|","|A|B|C|D|E|F|G|")),UPPER(TRIM('R1 respuestas'!B13)),"INVÁLIDO")) | C13: =IF(TRIM('R2 respuestas'!B13)="","",IF(ISNUMBER(SEARCH("|"&UPPER(TRIM('R2 respuestas'!B13))&"|","|A|B|C|D|E|F|G|")),UPPER(TRIM('R2 respuestas'!B13)),"INVÁLIDO")) | D13: =IF(OR(B13="",C13="",B13="INVÁLIDO",C13="INVÁLIDO"),"",IF(B13=C13,"sí","no")) | F13: =IF(OR(B13="",C13=""),"FALTA RESPUESTA",IF(OR(B13="INVÁLIDO",C13="INVÁLIDO"),"CÓDIGO INVÁLIDO",IF(IF(TRIM(E13)="","",IF(ISNUMBER(SEARCH("|"&UPPER(TRIM(E13))&"|","|A|B|C|D|E|F|G|")),UPPER(TRIM(E13)),"INVÁLIDO"))="INVÁLIDO","CONSENSO INVÁLIDO",IF(AND(D13="no",IF(TRIM(E13)="","",IF(ISNUMBER(SEARCH("|"&UPPER(TRIM(E13))&"|","|A|B|C|D|E|F|G|")),UPPER(TRIM(E13)),"INVÁLIDO"))=""),"FALTA CONSENSO","")))) -> FALTA RESPUESTA | G13: =IF(F13<>"","",IF(IF(TRIM(E13)="","",IF(ISNUMBER(SEARCH("|"&UPPER(TRIM(E13))&"|","|A|B|C|D|E|F|G|")),UPPER(TRIM(E13)),"INVÁLIDO"))<>"",IF(TRIM(E13)="","",IF(ISNUMBER(SEARCH("|"&UPPER(TRIM(E13))&"|","|A|B|C|D|E|F|G|")),UPPER(TRIM(E13)),"INVÁLIDO")),B13)) | H13: Acuerdo observado (po) | I13: =IF(I11=0,"",I12/I11)
A14: ='R1 respuestas'!A14 -> 13 | B14: =IF(TRIM('R1 respuestas'!B14)="","",IF(ISNUMBER(SEARCH("|"&UPPER(TRIM('R1 respuestas'!B14))&"|","|A|B|C|D|E|F|G|")),UPPER(TRIM('R1 respuestas'!B14)),"INVÁLIDO")) | C14: =IF(TRIM('R2 respuestas'!B14)="","",IF(ISNUMBER(SEARCH("|"&UPPER(TRIM('R2 respuestas'!B14))&"|","|A|B|C|D|E|F|G|")),UPPER(TRIM('R2 respuestas'!B14)),"INVÁLIDO")) | D14: =IF(OR(B14="",C14="",B14="INVÁLIDO",C14="INVÁLIDO"),"",IF(B14=C14,"sí","no")) | F14: =IF(OR(B14="",C14=""),"FALTA RESPUESTA",IF(OR(B14="INVÁLIDO",C14="INVÁLIDO"),"CÓDIGO INVÁLIDO",IF(IF(TRIM(E14)="","",IF(ISNUMBER(SEARCH("|"&UPPER(TRIM(E14))&"|","|A|B|C|D|E|F|G|")),UPPER(TRIM(E14)),"INVÁLIDO"))="INVÁLIDO","CONSENSO INVÁLIDO",IF(AND(D14="no",IF(TRIM(E14)="","",IF(ISNUMBER(SEARCH("|"&UPPER(TRIM(E14))&"|","|A|B|C|D|E|F|G|")),UPPER(TRIM(E14)),"INVÁLIDO"))=""),"FALTA CONSENSO","")))) -> FALTA RESPUESTA | G14: =IF(F14<>"","",IF(IF(TRIM(E14)="","",IF(ISNUMBER(SEARCH("|"&UPPER(TRIM(E14))&"|","|A|B|C|D|E|F|G|")),UPPER(TRIM(E14)),"INVÁLIDO"))<>"",IF(TRIM(E14)="","",IF(ISNUMBER(SEARCH("|"&UPPER(TRIM(E14))&"|","|A|B|C|D|E|F|G|")),UPPER(TRIM(E14)),"INVÁLIDO")),B14)) | H14: Acuerdo esperado al azar (pe) | I14: =IF(I11=0,"",SUM(R25:R31)/I11^2)
A15: ='R1 respuestas'!A15 -> 14 | B15: =IF(TRIM('R1 respuestas'!B15)="","",IF(ISNUMBER(SEARCH("|"&UPPER(TRIM('R1 respuestas'!B15))&"|","|A|B|C|D|E|F|G|")),UPPER(TRIM('R1 respuestas'!B15)),"INVÁLIDO")) | C15: =IF(TRIM('R2 respuestas'!B15)="","",IF(ISNUMBER(SEARCH("|"&UPPER(TRIM('R2 respuestas'!B15))&"|","|A|B|C|D|E|F|G|")),UPPER(TRIM('R2 respuestas'!B15)),"INVÁLIDO")) | D15: =IF(OR(B15="",C15="",B15="INVÁLIDO",C15="INVÁLIDO"),"",IF(B15=C15,"sí","no")) | F15: =IF(OR(B15="",C15=""),"FALTA RESPUESTA",IF(OR(B15="INVÁLIDO",C15="INVÁLIDO"),"CÓDIGO INVÁLIDO",IF(IF(TRIM(E15)="","",IF(ISNUMBER(SEARCH("|"&UPPER(TRIM(E15))&"|","|A|B|C|D|E|F|G|")),UPPER(TRIM(E15)),"INVÁLIDO"))="INVÁLIDO","CONSENSO INVÁLIDO",IF(AND(D15="no",IF(TRIM(E15)="","",IF(ISNUMBER(SEARCH("|"&UPPER(TRIM(E15))&"|","|A|B|C|D|E|F|G|")),UPPER(TRIM(E15)),"INVÁLIDO"))=""),"FALTA CONSENSO","")))) -> FALTA RESPUESTA | G15: =IF(F15<>"","",IF(IF(TRIM(E15)="","",IF(ISNUMBER(SEARCH("|"&UPPER(TRIM(E15))&"|","|A|B|C|D|E|F|G|")),UPPER(TRIM(E15)),"INVÁLIDO"))<>"",IF(TRIM(E15)="","",IF(ISNUMBER(SEARCH("|"&UPPER(TRIM(E15))&"|","|A|B|C|D|E|F|G|")),UPPER(TRIM(E15)),"INVÁLIDO")),B15)) | H15: Kappa de Cohen | I15: =IF(OR(I11=0,I14=1),"",(I13-I14)/(1-I14))
A16: ='R1 respuestas'!A16 -> 15 | B16: =IF(TRIM('R1 respuestas'!B16)="","",IF(ISNUMBER(SEARCH("|"&UPPER(TRIM('R1 respuestas'!B16))&"|","|A|B|C|D|E|F|G|")),UPPER(TRIM('R1 respuestas'!B16)),"INVÁLIDO")) | C16: =IF(TRIM('R2 respuestas'!B16)="","",IF(ISNUMBER(SEARCH("|"&UPPER(TRIM('R2 respuestas'!B16))&"|","|A|B|C|D|E|F|G|")),UPPER(TRIM('R2 respuestas'!B16)),"INVÁLIDO")) | D16: =IF(OR(B16="",C16="",B16="INVÁLIDO",C16="INVÁLIDO"),"",IF(B16=C16,"sí","no")) | F16: =IF(OR(B16="",C16=""),"FALTA RESPUESTA",IF(OR(B16="INVÁLIDO",C16="INVÁLIDO"),"CÓDIGO INVÁLIDO",IF(IF(TRIM(E16)="","",IF(ISNUMBER(SEARCH("|"&UPPER(TRIM(E16))&"|","|A|B|C|D|E|F|G|")),UPPER(TRIM(E16)),"INVÁLIDO"))="INVÁLIDO","CONSENSO INVÁLIDO",IF(AND(D16="no",IF(TRIM(E16)="","",IF(ISNUMBER(SEARCH("|"&UPPER(TRIM(E16))&"|","|A|B|C|D|E|F|G|")),UPPER(TRIM(E16)),"INVÁLIDO"))=""),"FALTA CONSENSO","")))) -> FALTA RESPUESTA | G16: =IF(F16<>"","",IF(IF(TRIM(E16)="","",IF(ISNUMBER(SEARCH("|"&UPPER(TRIM(E16))&"|","|A|B|C|D|E|F|G|")),UPPER(TRIM(E16)),"INVÁLIDO"))<>"",IF(TRIM(E16)="","",IF(ISNUMBER(SEARCH("|"&UPPER(TRIM(E16))&"|","|A|B|C|D|E|F|G|")),UPPER(TRIM(E16)),"INVÁLIDO")),B16)) | H16: IC 95 % para el paper: ver hoja «IC bootstrap» (kappa_bootstrap.py)
A17: ='R1 respuestas'!A17 -> 16 | B17: =IF(TRIM('R1 respuestas'!B17)="","",IF(ISNUMBER(SEARCH("|"&UPPER(TRIM('R1 respuestas'!B17))&"|","|A|B|C|D|E|F|G|")),UPPER(TRIM('R1 respuestas'!B17)),"INVÁLIDO")) | C17: =IF(TRIM('R2 respuestas'!B17)="","",IF(ISNUMBER(SEARCH("|"&UPPER(TRIM('R2 respuestas'!B17))&"|","|A|B|C|D|E|F|G|")),UPPER(TRIM('R2 respuestas'!B17)),"INVÁLIDO")) | D17: =IF(OR(B17="",C17="",B17="INVÁLIDO",C17="INVÁLIDO"),"",IF(B17=C17,"sí","no")) | F17: =IF(OR(B17="",C17=""),"FALTA RESPUESTA",IF(OR(B17="INVÁLIDO",C17="INVÁLIDO"),"CÓDIGO INVÁLIDO",IF(IF(TRIM(E17)="","",IF(ISNUMBER(SEARCH("|"&UPPER(TRIM(E17))&"|","|A|B|C|D|E|F|G|")),UPPER(TRIM(E17)),"INVÁLIDO"))="INVÁLIDO","CONSENSO INVÁLIDO",IF(AND(D17="no",IF(TRIM(E17)="","",IF(ISNUMBER(SEARCH("|"&UPPER(TRIM(E17))&"|","|A|B|C|D|E|F|G|")),UPPER(TRIM(E17)),"INVÁLIDO"))=""),"FALTA CONSENSO","")))) -> FALTA RESPUESTA | G17: =IF(F17<>"","",IF(IF(TRIM(E17)="","",IF(ISNUMBER(SEARCH("|"&UPPER(TRIM(E17))&"|","|A|B|C|D|E|F|G|")),UPPER(TRIM(E17)),"INVÁLIDO"))<>"",IF(TRIM(E17)="","",IF(ISNUMBER(SEARCH("|"&UPPER(TRIM(E17))&"|","|A|B|C|D|E|F|G|")),UPPER(TRIM(E17)),"INVÁLIDO")),B17))
A18: ='R1 respuestas'!A18 -> 17 | B18: =IF(TRIM('R1 respuestas'!B18)="","",IF(ISNUMBER(SEARCH("|"&UPPER(TRIM('R1 respuestas'!B18))&"|","|A|B|C|D|E|F|G|")),UPPER(TRIM('R1 respuestas'!B18)),"INVÁLIDO")) | C18: =IF(TRIM('R2 respuestas'!B18)="","",IF(ISNUMBER(SEARCH("|"&UPPER(TRIM('R2 respuestas'!B18))&"|","|A|B|C|D|E|F|G|")),UPPER(TRIM('R2 respuestas'!B18)),"INVÁLIDO")) | D18: =IF(OR(B18="",C18="",B18="INVÁLIDO",C18="INVÁLIDO"),"",IF(B18=C18,"sí","no")) | F18: =IF(OR(B18="",C18=""),"FALTA RESPUESTA",IF(OR(B18="INVÁLIDO",C18="INVÁLIDO"),"CÓDIGO INVÁLIDO",IF(IF(TRIM(E18)="","",IF(ISNUMBER(SEARCH("|"&UPPER(TRIM(E18))&"|","|A|B|C|D|E|F|G|")),UPPER(TRIM(E18)),"INVÁLIDO"))="INVÁLIDO","CONSENSO INVÁLIDO",IF(AND(D18="no",IF(TRIM(E18)="","",IF(ISNUMBER(SEARCH("|"&UPPER(TRIM(E18))&"|","|A|B|C|D|E|F|G|")),UPPER(TRIM(E18)),"INVÁLIDO"))=""),"FALTA CONSENSO","")))) -> FALTA RESPUESTA | G18: =IF(F18<>"","",IF(IF(TRIM(E18)="","",IF(ISNUMBER(SEARCH("|"&UPPER(TRIM(E18))&"|","|A|B|C|D|E|F|G|")),UPPER(TRIM(E18)),"INVÁLIDO"))<>"",IF(TRIM(E18)="","",IF(ISNUMBER(SEARCH("|"&UPPER(TRIM(E18))&"|","|A|B|C|D|E|F|G|")),UPPER(TRIM(E18)),"INVÁLIDO")),B18)) | H18: Comprobación opcional — NO reportar como resultado principal
A19: ='R1 respuestas'!A19 -> 18 | B19: =IF(TRIM('R1 respuestas'!B19)="","",IF(ISNUMBER(SEARCH("|"&UPPER(TRIM('R1 respuestas'!B19))&"|","|A|B|C|D|E|F|G|")),UPPER(TRIM('R1 respuestas'!B19)),"INVÁLIDO")) | C19: =IF(TRIM('R2 respuestas'!B19)="","",IF(ISNUMBER(SEARCH("|"&UPPER(TRIM('R2 respuestas'!B19))&"|","|A|B|C|D|E|F|G|")),UPPER(TRIM('R2 respuestas'!B19)),"INVÁLIDO")) | D19: =IF(OR(B19="",C19="",B19="INVÁLIDO",C19="INVÁLIDO"),"",IF(B19=C19,"sí","no")) | F19: =IF(OR(B19="",C19=""),"FALTA RESPUESTA",IF(OR(B19="INVÁLIDO",C19="INVÁLIDO"),"CÓDIGO INVÁLIDO",IF(IF(TRIM(E19)="","",IF(ISNUMBER(SEARCH("|"&UPPER(TRIM(E19))&"|","|A|B|C|D|E|F|G|")),UPPER(TRIM(E19)),"INVÁLIDO"))="INVÁLIDO","CONSENSO INVÁLIDO",IF(AND(D19="no",IF(TRIM(E19)="","",IF(ISNUMBER(SEARCH("|"&UPPER(TRIM(E19))&"|","|A|B|C|D|E|F|G|")),UPPER(TRIM(E19)),"INVÁLIDO"))=""),"FALTA CONSENSO","")))) -> FALTA RESPUESTA | G19: =IF(F19<>"","",IF(IF(TRIM(E19)="","",IF(ISNUMBER(SEARCH("|"&UPPER(TRIM(E19))&"|","|A|B|C|D|E|F|G|")),UPPER(TRIM(E19)),"INVÁLIDO"))<>"",IF(TRIM(E19)="","",IF(ISNUMBER(SEARCH("|"&UPPER(TRIM(E19))&"|","|A|B|C|D|E|F|G|")),UPPER(TRIM(E19)),"INVÁLIDO")),B19)) | H19: Error estándar (Fleiss, Cohen y Everitt 1969) | I19: =IF(I15="","",SQRT(MAX(0,SUM(S25:Y31)-(I15-I14*(1-I15))^2)/(I11*(1-I14)^2)))
A20: ='R1 respuestas'!A20 -> 19 | B20: =IF(TRIM('R1 respuestas'!B20)="","",IF(ISNUMBER(SEARCH("|"&UPPER(TRIM('R1 respuestas'!B20))&"|","|A|B|C|D|E|F|G|")),UPPER(TRIM('R1 respuestas'!B20)),"INVÁLIDO")) | C20: =IF(TRIM('R2 respuestas'!B20)="","",IF(ISNUMBER(SEARCH("|"&UPPER(TRIM('R2 respuestas'!B20))&"|","|A|B|C|D|E|F|G|")),UPPER(TRIM('R2 respuestas'!B20)),"INVÁLIDO")) | D20: =IF(OR(B20="",C20="",B20="INVÁLIDO",C20="INVÁLIDO"),"",IF(B20=C20,"sí","no")) | F20: =IF(OR(B20="",C20=""),"FALTA RESPUESTA",IF(OR(B20="INVÁLIDO",C20="INVÁLIDO"),"CÓDIGO INVÁLIDO",IF(IF(TRIM(E20)="","",IF(ISNUMBER(SEARCH("|"&UPPER(TRIM(E20))&"|","|A|B|C|D|E|F|G|")),UPPER(TRIM(E20)),"INVÁLIDO"))="INVÁLIDO","CONSENSO INVÁLIDO",IF(AND(D20="no",IF(TRIM(E20)="","",IF(ISNUMBER(SEARCH("|"&UPPER(TRIM(E20))&"|","|A|B|C|D|E|F|G|")),UPPER(TRIM(E20)),"INVÁLIDO"))=""),"FALTA CONSENSO","")))) -> FALTA RESPUESTA | G20: =IF(F20<>"","",IF(IF(TRIM(E20)="","",IF(ISNUMBER(SEARCH("|"&UPPER(TRIM(E20))&"|","|A|B|C|D|E|F|G|")),UPPER(TRIM(E20)),"INVÁLIDO"))<>"",IF(TRIM(E20)="","",IF(ISNUMBER(SEARCH("|"&UPPER(TRIM(E20))&"|","|A|B|C|D|E|F|G|")),UPPER(TRIM(E20)),"INVÁLIDO")),B20)) | H20: IC 95 % inferior (asintótico) | I20: =IF(I19="","",MAX(-1,I15-1.96*I19))
A21: ='R1 respuestas'!A21 -> 20 | B21: =IF(TRIM('R1 respuestas'!B21)="","",IF(ISNUMBER(SEARCH("|"&UPPER(TRIM('R1 respuestas'!B21))&"|","|A|B|C|D|E|F|G|")),UPPER(TRIM('R1 respuestas'!B21)),"INVÁLIDO")) | C21: =IF(TRIM('R2 respuestas'!B21)="","",IF(ISNUMBER(SEARCH("|"&UPPER(TRIM('R2 respuestas'!B21))&"|","|A|B|C|D|E|F|G|")),UPPER(TRIM('R2 respuestas'!B21)),"INVÁLIDO")) | D21: =IF(OR(B21="",C21="",B21="INVÁLIDO",C21="INVÁLIDO"),"",IF(B21=C21,"sí","no")) | F21: =IF(OR(B21="",C21=""),"FALTA RESPUESTA",IF(OR(B21="INVÁLIDO",C21="INVÁLIDO"),"CÓDIGO INVÁLIDO",IF(IF(TRIM(E21)="","",IF(ISNUMBER(SEARCH("|"&UPPER(TRIM(E21))&"|","|A|B|C|D|E|F|G|")),UPPER(TRIM(E21)),"INVÁLIDO"))="INVÁLIDO","CONSENSO INVÁLIDO",IF(AND(D21="no",IF(TRIM(E21)="","",IF(ISNUMBER(SEARCH("|"&UPPER(TRIM(E21))&"|","|A|B|C|D|E|F|G|")),UPPER(TRIM(E21)),"INVÁLIDO"))=""),"FALTA CONSENSO","")))) -> FALTA RESPUESTA | G21: =IF(F21<>"","",IF(IF(TRIM(E21)="","",IF(ISNUMBER(SEARCH("|"&UPPER(TRIM(E21))&"|","|A|B|C|D|E|F|G|")),UPPER(TRIM(E21)),"INVÁLIDO"))<>"",IF(TRIM(E21)="","",IF(ISNUMBER(SEARCH("|"&UPPER(TRIM(E21))&"|","|A|B|C|D|E|F|G|")),UPPER(TRIM(E21)),"INVÁLIDO")),B21)) | H21: IC 95 % superior (asintótico) | I21: =IF(I19="","",MIN(1,I15+1.96*I19))
A22: ='R1 respuestas'!A22 -> 21 | B22: =IF(TRIM('R1 respuestas'!B22)="","",IF(ISNUMBER(SEARCH("|"&UPPER(TRIM('R1 respuestas'!B22))&"|","|A|B|C|D|E|F|G|")),UPPER(TRIM('R1 respuestas'!B22)),"INVÁLIDO")) | C22: =IF(TRIM('R2 respuestas'!B22)="","",IF(ISNUMBER(SEARCH("|"&UPPER(TRIM('R2 respuestas'!B22))&"|","|A|B|C|D|E|F|G|")),UPPER(TRIM('R2 respuestas'!B22)),"INVÁLIDO")) | D22: =IF(OR(B22="",C22="",B22="INVÁLIDO",C22="INVÁLIDO"),"",IF(B22=C22,"sí","no")) | F22: =IF(OR(B22="",C22=""),"FALTA RESPUESTA",IF(OR(B22="INVÁLIDO",C22="INVÁLIDO"),"CÓDIGO INVÁLIDO",IF(IF(TRIM(E22)="","",IF(ISNUMBER(SEARCH("|"&UPPER(TRIM(E22))&"|","|A|B|C|D|E|F|G|")),UPPER(TRIM(E22)),"INVÁLIDO"))="INVÁLIDO","CONSENSO INVÁLIDO",IF(AND(D22="no",IF(TRIM(E22)="","",IF(ISNUMBER(SEARCH("|"&UPPER(TRIM(E22))&"|","|A|B|C|D|E|F|G|")),UPPER(TRIM(E22)),"INVÁLIDO"))=""),"FALTA CONSENSO","")))) -> FALTA RESPUESTA | G22: =IF(F22<>"","",IF(IF(TRIM(E22)="","",IF(ISNUMBER(SEARCH("|"&UPPER(TRIM(E22))&"|","|A|B|C|D|E|F|G|")),UPPER(TRIM(E22)),"INVÁLIDO"))<>"",IF(TRIM(E22)="","",IF(ISNUMBER(SEARCH("|"&UPPER(TRIM(E22))&"|","|A|B|C|D|E|F|G|")),UPPER(TRIM(E22)),"INVÁLIDO")),B22))
A23: ='R1 respuestas'!A23 -> 22 | B23: =IF(TRIM('R1 respuestas'!B23)="","",IF(ISNUMBER(SEARCH("|"&UPPER(TRIM('R1 respuestas'!B23))&"|","|A|B|C|D|E|F|G|")),UPPER(TRIM('R1 respuestas'!B23)),"INVÁLIDO")) | C23: =IF(TRIM('R2 respuestas'!B23)="","",IF(ISNUMBER(SEARCH("|"&UPPER(TRIM('R2 respuestas'!B23))&"|","|A|B|C|D|E|F|G|")),UPPER(TRIM('R2 respuestas'!B23)),"INVÁLIDO")) | D23: =IF(OR(B23="",C23="",B23="INVÁLIDO",C23="INVÁLIDO"),"",IF(B23=C23,"sí","no")) | F23: =IF(OR(B23="",C23=""),"FALTA RESPUESTA",IF(OR(B23="INVÁLIDO",C23="INVÁLIDO"),"CÓDIGO INVÁLIDO",IF(IF(TRIM(E23)="","",IF(ISNUMBER(SEARCH("|"&UPPER(TRIM(E23))&"|","|A|B|C|D|E|F|G|")),UPPER(TRIM(E23)),"INVÁLIDO"))="INVÁLIDO","CONSENSO INVÁLIDO",IF(AND(D23="no",IF(TRIM(E23)="","",IF(ISNUMBER(SEARCH("|"&UPPER(TRIM(E23))&"|","|A|B|C|D|E|F|G|")),UPPER(TRIM(E23)),"INVÁLIDO"))=""),"FALTA CONSENSO","")))) -> FALTA RESPUESTA | G23: =IF(F23<>"","",IF(IF(TRIM(E23)="","",IF(ISNUMBER(SEARCH("|"&UPPER(TRIM(E23))&"|","|A|B|C|D|E|F|G|")),UPPER(TRIM(E23)),"INVÁLIDO"))<>"",IF(TRIM(E23)="","",IF(ISNUMBER(SEARCH("|"&UPPER(TRIM(E23))&"|","|A|B|C|D|E|F|G|")),UPPER(TRIM(E23)),"INVÁLIDO")),B23)) | H23: Matriz de confusión (filas: Revisor 1; columnas: Revisor 2) | S23: Términos de la varianza de Fleiss (auxiliar)
A24: ='R1 respuestas'!A24 -> 23 | B24: =IF(TRIM('R1 respuestas'!B24)="","",IF(ISNUMBER(SEARCH("|"&UPPER(TRIM('R1 respuestas'!B24))&"|","|A|B|C|D|E|F|G|")),UPPER(TRIM('R1 respuestas'!B24)),"INVÁLIDO")) | C24: =IF(TRIM('R2 respuestas'!B24)="","",IF(ISNUMBER(SEARCH("|"&UPPER(TRIM('R2 respuestas'!B24))&"|","|A|B|C|D|E|F|G|")),UPPER(TRIM('R2 respuestas'!B24)),"INVÁLIDO")) | D24: =IF(OR(B24="",C24="",B24="INVÁLIDO",C24="INVÁLIDO"),"",IF(B24=C24,"sí","no")) | F24: =IF(OR(B24="",C24=""),"FALTA RESPUESTA",IF(OR(B24="INVÁLIDO",C24="INVÁLIDO"),"CÓDIGO INVÁLIDO",IF(IF(TRIM(E24)="","",IF(ISNUMBER(SEARCH("|"&UPPER(TRIM(E24))&"|","|A|B|C|D|E|F|G|")),UPPER(TRIM(E24)),"INVÁLIDO"))="INVÁLIDO","CONSENSO INVÁLIDO",IF(AND(D24="no",IF(TRIM(E24)="","",IF(ISNUMBER(SEARCH("|"&UPPER(TRIM(E24))&"|","|A|B|C|D|E|F|G|")),UPPER(TRIM(E24)),"INVÁLIDO"))=""),"FALTA CONSENSO","")))) -> FALTA RESPUESTA | G24: =IF(F24<>"","",IF(IF(TRIM(E24)="","",IF(ISNUMBER(SEARCH("|"&UPPER(TRIM(E24))&"|","|A|B|C|D|E|F|G|")),UPPER(TRIM(E24)),"INVÁLIDO"))<>"",IF(TRIM(E24)="","",IF(ISNUMBER(SEARCH("|"&UPPER(TRIM(E24))&"|","|A|B|C|D|E|F|G|")),UPPER(TRIM(E24)),"INVÁLIDO")),B24)) | H24: R1 \ R2 | I24: A | J24: B | K24: C | L24: D | M24: E | N24: F | O24: G | P24: Total R1 | R24: pi·pj (pe)
A25: ='R1 respuestas'!A25 -> 24 | B25: =IF(TRIM('R1 respuestas'!B25)="","",IF(ISNUMBER(SEARCH("|"&UPPER(TRIM('R1 respuestas'!B25))&"|","|A|B|C|D|E|F|G|")),UPPER(TRIM('R1 respuestas'!B25)),"INVÁLIDO")) | C25: =IF(TRIM('R2 respuestas'!B25)="","",IF(ISNUMBER(SEARCH("|"&UPPER(TRIM('R2 respuestas'!B25))&"|","|A|B|C|D|E|F|G|")),UPPER(TRIM('R2 respuestas'!B25)),"INVÁLIDO")) | D25: =IF(OR(B25="",C25="",B25="INVÁLIDO",C25="INVÁLIDO"),"",IF(B25=C25,"sí","no")) | F25: =IF(OR(B25="",C25=""),"FALTA RESPUESTA",IF(OR(B25="INVÁLIDO",C25="INVÁLIDO"),"CÓDIGO INVÁLIDO",IF(IF(TRIM(E25)="","",IF(ISNUMBER(SEARCH("|"&UPPER(TRIM(E25))&"|","|A|B|C|D|E|F|G|")),UPPER(TRIM(E25)),"INVÁLIDO"))="INVÁLIDO","CONSENSO INVÁLIDO",IF(AND(D25="no",IF(TRIM(E25)="","",IF(ISNUMBER(SEARCH("|"&UPPER(TRIM(E25))&"|","|A|B|C|D|E|F|G|")),UPPER(TRIM(E25)),"INVÁLIDO"))=""),"FALTA CONSENSO","")))) -> FALTA RESPUESTA | G25: =IF(F25<>"","",IF(IF(TRIM(E25)="","",IF(ISNUMBER(SEARCH("|"&UPPER(TRIM(E25))&"|","|A|B|C|D|E|F|G|")),UPPER(TRIM(E25)),"INVÁLIDO"))<>"",IF(TRIM(E25)="","",IF(ISNUMBER(SEARCH("|"&UPPER(TRIM(E25))&"|","|A|B|C|D|E|F|G|")),UPPER(TRIM(E25)),"INVÁLIDO")),B25)) | H25: A. Vehículo que se cruza o se cierra delante | I25: =COUNTIFS($B$2:$B$29,"A",$C$2:$C$29,"A") -> 0 | J25: =COUNTIFS($B$2:$B$29,"A",$C$2:$C$29,"B") -> 0 | K25: =COUNTIFS($B$2:$B$29,"A",$C$2:$C$29,"C") -> 0 | L25: =COUNTIFS($B$2:$B$29,"A",$C$2:$C$29,"D") -> 0 | M25: =COUNTIFS($B$2:$B$29,"A",$C$2:$C$29,"E") -> 0 | N25: =COUNTIFS($B$2:$B$29,"A",$C$2:$C$29,"F") -> 0 | O25: =COUNTIFS($B$2:$B$29,"A",$C$2:$C$29,"G") -> 0 | P25: =SUM(I25:O25) -> 0 | R25: =P25*I$32 -> 0 | S25: =IF($I$15="",0,I25/$I$11*(1-(P25+I$32)/$I$11*(1-$I$15))^2) -> 0 | T25: =IF($I$15="",0,(1-$I$15)^2*J25/$I$11*((I$32+$P$26)/$I$11)^2) -> 0 | U25: =IF($I$15="",0,(1-$I$15)^2*K25/$I$11*((I$32+$P$27)/$I$11)^2) -> 0 | V25: =IF($I$15="",0,(1-$I$15)^2*L25/$I$11*((I$32+$P$28)/$I$11)^2) -> 0 | W25: =IF($I$15="",0,(1-$I$15)^2*M25/$I$11*((I$32+$P$29)/$I$11)^2) -> 0 | X25: =IF($I$15="",0,(1-$I$15)^2*N25/$I$11*((I$32+$P$30)/$I$11)^2) -> 0 | Y25: =IF($I$15="",0,(1-$I$15)^2*O25/$I$11*((I$32+$P$31)/$I$11)^2) -> 0
A26: ='R1 respuestas'!A26 -> 25 | B26: =IF(TRIM('R1 respuestas'!B26)="","",IF(ISNUMBER(SEARCH("|"&UPPER(TRIM('R1 respuestas'!B26))&"|","|A|B|C|D|E|F|G|")),UPPER(TRIM('R1 respuestas'!B26)),"INVÁLIDO")) | C26: =IF(TRIM('R2 respuestas'!B26)="","",IF(ISNUMBER(SEARCH("|"&UPPER(TRIM('R2 respuestas'!B26))&"|","|A|B|C|D|E|F|G|")),UPPER(TRIM('R2 respuestas'!B26)),"INVÁLIDO")) | D26: =IF(OR(B26="",C26="",B26="INVÁLIDO",C26="INVÁLIDO"),"",IF(B26=C26,"sí","no")) | F26: =IF(OR(B26="",C26=""),"FALTA RESPUESTA",IF(OR(B26="INVÁLIDO",C26="INVÁLIDO"),"CÓDIGO INVÁLIDO",IF(IF(TRIM(E26)="","",IF(ISNUMBER(SEARCH("|"&UPPER(TRIM(E26))&"|","|A|B|C|D|E|F|G|")),UPPER(TRIM(E26)),"INVÁLIDO"))="INVÁLIDO","CONSENSO INVÁLIDO",IF(AND(D26="no",IF(TRIM(E26)="","",IF(ISNUMBER(SEARCH("|"&UPPER(TRIM(E26))&"|","|A|B|C|D|E|F|G|")),UPPER(TRIM(E26)),"INVÁLIDO"))=""),"FALTA CONSENSO","")))) -> FALTA RESPUESTA | G26: =IF(F26<>"","",IF(IF(TRIM(E26)="","",IF(ISNUMBER(SEARCH("|"&UPPER(TRIM(E26))&"|","|A|B|C|D|E|F|G|")),UPPER(TRIM(E26)),"INVÁLIDO"))<>"",IF(TRIM(E26)="","",IF(ISNUMBER(SEARCH("|"&UPPER(TRIM(E26))&"|","|A|B|C|D|E|F|G|")),UPPER(TRIM(E26)),"INVÁLIDO")),B26)) | H26: B. Vehículo adyacente que pasa muy cerca | I26: =COUNTIFS($B$2:$B$29,"B",$C$2:$C$29,"A") -> 0 | J26: =COUNTIFS($B$2:$B$29,"B",$C$2:$C$29,"B") -> 0 | K26: =COUNTIFS($B$2:$B$29,"B",$C$2:$C$29,"C") -> 0 | L26: =COUNTIFS($B$2:$B$29,"B",$C$2:$C$29,"D") -> 0 | M26: =COUNTIFS($B$2:$B$29,"B",$C$2:$C$29,"E") -> 0 | N26: =COUNTIFS($B$2:$B$29,"B",$C$2:$C$29,"F") -> 0 | O26: =COUNTIFS($B$2:$B$29,"B",$C$2:$C$29,"G") -> 0 | P26: =SUM(I26:O26) -> 0 | R26: =P26*J$32 -> 0 | S26: =IF($I$15="",0,(1-$I$15)^2*I26/$I$11*((J$32+$P$25)/$I$11)^2) -> 0 | T26: =IF($I$15="",0,J26/$I$11*(1-(P26+J$32)/$I$11*(1-$I$15))^2) -> 0 | U26: =IF($I$15="",0,(1-$I$15)^2*K26/$I$11*((J$32+$P$27)/$I$11)^2) -> 0 | V26: =IF($I$15="",0,(1-$I$15)^2*L26/$I$11*((J$32+$P$28)/$I$11)^2) -> 0 | W26: =IF($I$15="",0,(1-$I$15)^2*M26/$I$11*((J$32+$P$29)/$I$11)^2) -> 0 | X26: =IF($I$15="",0,(1-$I$15)^2*N26/$I$11*((J$32+$P$30)/$I$11)^2) -> 0 | Y26: =IF($I$15="",0,(1-$I$15)^2*O26/$I$11*((J$32+$P$31)/$I$11)^2) -> 0
A27: ='R1 respuestas'!A27 -> 26 | B27: =IF(TRIM('R1 respuestas'!B27)="","",IF(ISNUMBER(SEARCH("|"&UPPER(TRIM('R1 respuestas'!B27))&"|","|A|B|C|D|E|F|G|")),UPPER(TRIM('R1 respuestas'!B27)),"INVÁLIDO")) | C27: =IF(TRIM('R2 respuestas'!B27)="","",IF(ISNUMBER(SEARCH("|"&UPPER(TRIM('R2 respuestas'!B27))&"|","|A|B|C|D|E|F|G|")),UPPER(TRIM('R2 respuestas'!B27)),"INVÁLIDO")) | D27: =IF(OR(B27="",C27="",B27="INVÁLIDO",C27="INVÁLIDO"),"",IF(B27=C27,"sí","no")) | F27: =IF(OR(B27="",C27=""),"FALTA RESPUESTA",IF(OR(B27="INVÁLIDO",C27="INVÁLIDO"),"CÓDIGO INVÁLIDO",IF(IF(TRIM(E27)="","",IF(ISNUMBER(SEARCH("|"&UPPER(TRIM(E27))&"|","|A|B|C|D|E|F|G|")),UPPER(TRIM(E27)),"INVÁLIDO"))="INVÁLIDO","CONSENSO INVÁLIDO",IF(AND(D27="no",IF(TRIM(E27)="","",IF(ISNUMBER(SEARCH("|"&UPPER(TRIM(E27))&"|","|A|B|C|D|E|F|G|")),UPPER(TRIM(E27)),"INVÁLIDO"))=""),"FALTA CONSENSO","")))) -> FALTA RESPUESTA | G27: =IF(F27<>"","",IF(IF(TRIM(E27)="","",IF(ISNUMBER(SEARCH("|"&UPPER(TRIM(E27))&"|","|A|B|C|D|E|F|G|")),UPPER(TRIM(E27)),"INVÁLIDO"))<>"",IF(TRIM(E27)="","",IF(ISNUMBER(SEARCH("|"&UPPER(TRIM(E27))&"|","|A|B|C|D|E|F|G|")),UPPER(TRIM(E27)),"INVÁLIDO")),B27)) | H27: C. Objetos fijos al borde de la vía | I27: =COUNTIFS($B$2:$B$29,"C",$C$2:$C$29,"A") -> 0 | J27: =COUNTIFS($B$2:$B$29,"C",$C$2:$C$29,"B") -> 0 | K27: =COUNTIFS($B$2:$B$29,"C",$C$2:$C$29,"C") -> 0 | L27: =COUNTIFS($B$2:$B$29,"C",$C$2:$C$29,"D") -> 0 | M27: =COUNTIFS($B$2:$B$29,"C",$C$2:$C$29,"E") -> 0 | N27: =COUNTIFS($B$2:$B$29,"C",$C$2:$C$29,"F") -> 0 | O27: =COUNTIFS($B$2:$B$29,"C",$C$2:$C$29,"G") -> 0 | P27: =SUM(I27:O27) -> 0 | R27: =P27*K$32 -> 0 | S27: =IF($I$15="",0,(1-$I$15)^2*I27/$I$11*((K$32+$P$25)/$I$11)^2) -> 0 | T27: =IF($I$15="",0,(1-$I$15)^2*J27/$I$11*((K$32+$P$26)/$I$11)^2) -> 0 | U27: =IF($I$15="",0,K27/$I$11*(1-(P27+K$32)/$I$11*(1-$I$15))^2) -> 0 | V27: =IF($I$15="",0,(1-$I$15)^2*L27/$I$11*((K$32+$P$28)/$I$11)^2) -> 0 | W27: =IF($I$15="",0,(1-$I$15)^2*M27/$I$11*((K$32+$P$29)/$I$11)^2) -> 0 | X27: =IF($I$15="",0,(1-$I$15)^2*N27/$I$11*((K$32+$P$30)/$I$11)^2) -> 0 | Y27: =IF($I$15="",0,(1-$I$15)^2*O27/$I$11*((K$32+$P$31)/$I$11)^2) -> 0
A28: ='R1 respuestas'!A28 -> 27 | B28: =IF(TRIM('R1 respuestas'!B28)="","",IF(ISNUMBER(SEARCH("|"&UPPER(TRIM('R1 respuestas'!B28))&"|","|A|B|C|D|E|F|G|")),UPPER(TRIM('R1 respuestas'!B28)),"INVÁLIDO")) | C28: =IF(TRIM('R2 respuestas'!B28)="","",IF(ISNUMBER(SEARCH("|"&UPPER(TRIM('R2 respuestas'!B28))&"|","|A|B|C|D|E|F|G|")),UPPER(TRIM('R2 respuestas'!B28)),"INVÁLIDO")) | D28: =IF(OR(B28="",C28="",B28="INVÁLIDO",C28="INVÁLIDO"),"",IF(B28=C28,"sí","no")) | F28: =IF(OR(B28="",C28=""),"FALTA RESPUESTA",IF(OR(B28="INVÁLIDO",C28="INVÁLIDO"),"CÓDIGO INVÁLIDO",IF(IF(TRIM(E28)="","",IF(ISNUMBER(SEARCH("|"&UPPER(TRIM(E28))&"|","|A|B|C|D|E|F|G|")),UPPER(TRIM(E28)),"INVÁLIDO"))="INVÁLIDO","CONSENSO INVÁLIDO",IF(AND(D28="no",IF(TRIM(E28)="","",IF(ISNUMBER(SEARCH("|"&UPPER(TRIM(E28))&"|","|A|B|C|D|E|F|G|")),UPPER(TRIM(E28)),"INVÁLIDO"))=""),"FALTA CONSENSO","")))) -> FALTA RESPUESTA | G28: =IF(F28<>"","",IF(IF(TRIM(E28)="","",IF(ISNUMBER(SEARCH("|"&UPPER(TRIM(E28))&"|","|A|B|C|D|E|F|G|")),UPPER(TRIM(E28)),"INVÁLIDO"))<>"",IF(TRIM(E28)="","",IF(ISNUMBER(SEARCH("|"&UPPER(TRIM(E28))&"|","|A|B|C|D|E|F|G|")),UPPER(TRIM(E28)),"INVÁLIDO")),B28)) | H28: D. Giro o curva del vehículo propio | I28: =COUNTIFS($B$2:$B$29,"D",$C$2:$C$29,"A") -> 0 | J28: =COUNTIFS($B$2:$B$29,"D",$C$2:$C$29,"B") -> 0 | K28: =COUNTIFS($B$2:$B$29,"D",$C$2:$C$29,"C") -> 0 | L28: =COUNTIFS($B$2:$B$29,"D",$C$2:$C$29,"D") -> 0 | M28: =COUNTIFS($B$2:$B$29,"D",$C$2:$C$29,"E") -> 0 | N28: =COUNTIFS($B$2:$B$29,"D",$C$2:$C$29,"F") -> 0 | O28: =COUNTIFS($B$2:$B$29,"D",$C$2:$C$29,"G") -> 0 | P28: =SUM(I28:O28) -> 0 | R28: =P28*L$32 -> 0 | S28: =IF($I$15="",0,(1-$I$15)^2*I28/$I$11*((L$32+$P$25)/$I$11)^2) -> 0 | T28: =IF($I$15="",0,(1-$I$15)^2*J28/$I$11*((L$32+$P$26)/$I$11)^2) -> 0 | U28: =IF($I$15="",0,(1-$I$15)^2*K28/$I$11*((L$32+$P$27)/$I$11)^2) -> 0 | V28: =IF($I$15="",0,L28/$I$11*(1-(P28+L$32)/$I$11*(1-$I$15))^2) -> 0 | W28: =IF($I$15="",0,(1-$I$15)^2*M28/$I$11*((L$32+$P$29)/$I$11)^2) -> 0 | X28: =IF($I$15="",0,(1-$I$15)^2*N28/$I$11*((L$32+$P$30)/$I$11)^2) -> 0 | Y28: =IF($I$15="",0,(1-$I$15)^2*O28/$I$11*((L$32+$P$31)/$I$11)^2) -> 0
A29: ='R1 respuestas'!A29 -> 28 | B29: =IF(TRIM('R1 respuestas'!B29)="","",IF(ISNUMBER(SEARCH("|"&UPPER(TRIM('R1 respuestas'!B29))&"|","|A|B|C|D|E|F|G|")),UPPER(TRIM('R1 respuestas'!B29)),"INVÁLIDO")) | C29: =IF(TRIM('R2 respuestas'!B29)="","",IF(ISNUMBER(SEARCH("|"&UPPER(TRIM('R2 respuestas'!B29))&"|","|A|B|C|D|E|F|G|")),UPPER(TRIM('R2 respuestas'!B29)),"INVÁLIDO")) | D29: =IF(OR(B29="",C29="",B29="INVÁLIDO",C29="INVÁLIDO"),"",IF(B29=C29,"sí","no")) | F29: =IF(OR(B29="",C29=""),"FALTA RESPUESTA",IF(OR(B29="INVÁLIDO",C29="INVÁLIDO"),"CÓDIGO INVÁLIDO",IF(IF(TRIM(E29)="","",IF(ISNUMBER(SEARCH("|"&UPPER(TRIM(E29))&"|","|A|B|C|D|E|F|G|")),UPPER(TRIM(E29)),"INVÁLIDO"))="INVÁLIDO","CONSENSO INVÁLIDO",IF(AND(D29="no",IF(TRIM(E29)="","",IF(ISNUMBER(SEARCH("|"&UPPER(TRIM(E29))&"|","|A|B|C|D|E|F|G|")),UPPER(TRIM(E29)),"INVÁLIDO"))=""),"FALTA CONSENSO","")))) -> FALTA RESPUESTA | G29: =IF(F29<>"","",IF(IF(TRIM(E29)="","",IF(ISNUMBER(SEARCH("|"&UPPER(TRIM(E29))&"|","|A|B|C|D|E|F|G|")),UPPER(TRIM(E29)),"INVÁLIDO"))<>"",IF(TRIM(E29)="","",IF(ISNUMBER(SEARCH("|"&UPPER(TRIM(E29))&"|","|A|B|C|D|E|F|G|")),UPPER(TRIM(E29)),"INVÁLIDO")),B29)) | H29: E. Paso a desnivel o cambio de luz | I29: =COUNTIFS($B$2:$B$29,"E",$C$2:$C$29,"A") -> 0 | J29: =COUNTIFS($B$2:$B$29,"E",$C$2:$C$29,"B") -> 0 | K29: =COUNTIFS($B$2:$B$29,"E",$C$2:$C$29,"C") -> 0 | L29: =COUNTIFS($B$2:$B$29,"E",$C$2:$C$29,"D") -> 0 | M29: =COUNTIFS($B$2:$B$29,"E",$C$2:$C$29,"E") -> 0 | N29: =COUNTIFS($B$2:$B$29,"E",$C$2:$C$29,"F") -> 0 | O29: =COUNTIFS($B$2:$B$29,"E",$C$2:$C$29,"G") -> 0 | P29: =SUM(I29:O29) -> 0 | R29: =P29*M$32 -> 0 | S29: =IF($I$15="",0,(1-$I$15)^2*I29/$I$11*((M$32+$P$25)/$I$11)^2) -> 0 | T29: =IF($I$15="",0,(1-$I$15)^2*J29/$I$11*((M$32+$P$26)/$I$11)^2) -> 0 | U29: =IF($I$15="",0,(1-$I$15)^2*K29/$I$11*((M$32+$P$27)/$I$11)^2) -> 0 | V29: =IF($I$15="",0,(1-$I$15)^2*L29/$I$11*((M$32+$P$28)/$I$11)^2) -> 0 | W29: =IF($I$15="",0,M29/$I$11*(1-(P29+M$32)/$I$11*(1-$I$15))^2) -> 0 | X29: =IF($I$15="",0,(1-$I$15)^2*N29/$I$11*((M$32+$P$30)/$I$11)^2) -> 0 | Y29: =IF($I$15="",0,(1-$I$15)^2*O29/$I$11*((M$32+$P$31)/$I$11)^2) -> 0
H30: F. Marcas pintadas en la pista | I30: =COUNTIFS($B$2:$B$29,"F",$C$2:$C$29,"A") -> 0 | J30: =COUNTIFS($B$2:$B$29,"F",$C$2:$C$29,"B") -> 0 | K30: =COUNTIFS($B$2:$B$29,"F",$C$2:$C$29,"C") -> 0 | L30: =COUNTIFS($B$2:$B$29,"F",$C$2:$C$29,"D") -> 0 | M30: =COUNTIFS($B$2:$B$29,"F",$C$2:$C$29,"E") -> 0 | N30: =COUNTIFS($B$2:$B$29,"F",$C$2:$C$29,"F") -> 0 | O30: =COUNTIFS($B$2:$B$29,"F",$C$2:$C$29,"G") -> 0 | P30: =SUM(I30:O30) -> 0 | R30: =P30*N$32 -> 0 | S30: =IF($I$15="",0,(1-$I$15)^2*I30/$I$11*((N$32+$P$25)/$I$11)^2) -> 0 | T30: =IF($I$15="",0,(1-$I$15)^2*J30/$I$11*((N$32+$P$26)/$I$11)^2) -> 0 | U30: =IF($I$15="",0,(1-$I$15)^2*K30/$I$11*((N$32+$P$27)/$I$11)^2) -> 0 | V30: =IF($I$15="",0,(1-$I$15)^2*L30/$I$11*((N$32+$P$28)/$I$11)^2) -> 0 | W30: =IF($I$15="",0,(1-$I$15)^2*M30/$I$11*((N$32+$P$29)/$I$11)^2) -> 0 | X30: =IF($I$15="",0,N30/$I$11*(1-(P30+N$32)/$I$11*(1-$I$15))^2) -> 0 | Y30: =IF($I$15="",0,(1-$I$15)^2*O30/$I$11*((N$32+$P$31)/$I$11)^2) -> 0
H31: G. Otra o no determinable | I31: =COUNTIFS($B$2:$B$29,"G",$C$2:$C$29,"A") -> 0 | J31: =COUNTIFS($B$2:$B$29,"G",$C$2:$C$29,"B") -> 0 | K31: =COUNTIFS($B$2:$B$29,"G",$C$2:$C$29,"C") -> 0 | L31: =COUNTIFS($B$2:$B$29,"G",$C$2:$C$29,"D") -> 0 | M31: =COUNTIFS($B$2:$B$29,"G",$C$2:$C$29,"E") -> 0 | N31: =COUNTIFS($B$2:$B$29,"G",$C$2:$C$29,"F") -> 0 | O31: =COUNTIFS($B$2:$B$29,"G",$C$2:$C$29,"G") -> 0 | P31: =SUM(I31:O31) -> 0 | R31: =P31*O$32 -> 0 | S31: =IF($I$15="",0,(1-$I$15)^2*I31/$I$11*((O$32+$P$25)/$I$11)^2) -> 0 | T31: =IF($I$15="",0,(1-$I$15)^2*J31/$I$11*((O$32+$P$26)/$I$11)^2) -> 0 | U31: =IF($I$15="",0,(1-$I$15)^2*K31/$I$11*((O$32+$P$27)/$I$11)^2) -> 0 | V31: =IF($I$15="",0,(1-$I$15)^2*L31/$I$11*((O$32+$P$28)/$I$11)^2) -> 0 | W31: =IF($I$15="",0,(1-$I$15)^2*M31/$I$11*((O$32+$P$29)/$I$11)^2) -> 0 | X31: =IF($I$15="",0,(1-$I$15)^2*N31/$I$11*((O$32+$P$30)/$I$11)^2) -> 0 | Y31: =IF($I$15="",0,O31/$I$11*(1-(P31+O$32)/$I$11*(1-$I$15))^2) -> 0
H32: Total R2 | I32: =SUM(I25:I31) -> 0 | J32: =SUM(J25:J31) -> 0 | K32: =SUM(K25:K31) -> 0 | L32: =SUM(L25:L31) -> 0 | M32: =SUM(M25:M31) -> 0 | N32: =SUM(N25:N31) -> 0 | O32: =SUM(O25:O31) -> 0 | P32: =SUM(P25:P31) -> 0
H34: Distribución final (tras consenso)
H35: Causa | I35: Eventos | J35: % de eventos finales
H36: A. Vehículo que se cruza o se cierra delante | I36: =COUNTIF(G$2:G$29,"A") -> 0 | J36: =IF(SUM(I$36:I$42)=0,"",I36/SUM(I$36:I$42))
H37: B. Vehículo adyacente que pasa muy cerca | I37: =COUNTIF(G$2:G$29,"B") -> 0 | J37: =IF(SUM(I$36:I$42)=0,"",I37/SUM(I$36:I$42))
H38: C. Objetos fijos al borde de la vía | I38: =COUNTIF(G$2:G$29,"C") -> 0 | J38: =IF(SUM(I$36:I$42)=0,"",I38/SUM(I$36:I$42))
H39: D. Giro o curva del vehículo propio | I39: =COUNTIF(G$2:G$29,"D") -> 0 | J39: =IF(SUM(I$36:I$42)=0,"",I39/SUM(I$36:I$42))
H40: E. Paso a desnivel o cambio de luz | I40: =COUNTIF(G$2:G$29,"E") -> 0 | J40: =IF(SUM(I$36:I$42)=0,"",I40/SUM(I$36:I$42))
H41: F. Marcas pintadas en la pista | I41: =COUNTIF(G$2:G$29,"F") -> 0 | J41: =IF(SUM(I$36:I$42)=0,"",I41/SUM(I$36:I$42))
...

Sheet IC bootstrap
A1: Se llena al ejecutar kappa_bootstrap.py (no editar a mano)
A3: Fecha de cálculo | B3: —
A4: n eventos | B4: —
A5: Acuerdo observado | B5: —
A6: Kappa | B6: —
A7: IC 95 % inferior | B7: —
A8: IC 95 % superior | B8: —
A9: Réplicas válidas | B9: —
A10: Método | B10: —
A11: Frase para el paper | B11: —
